<mujoco model="ur5e scene">
<!-- ENGINE SETUP -->
  <compiler angle="radian" meshdir="universal_robots_ur5e/assets" autolimits="true"/>
  <option>
    <flag multiccd="enable"/>
  </option>
  <statistic center="0.3 0 0.4" extent="3"/>

<!-- Defaults -->
  <default class="main">
    <default class="small_enc">
      <geom size="0.01 0.01 0.5" type="box" rgba="0 0 0.3 0.2" condim="1"/>
    </default>
    <default class="large_enc">
      <geom size="0.01 0.08 0.5" type="box" rgba="0 0 0.3 0.2" condim="1"/>
    </default>
    <default class="boxes">
      <geom type="box" size="0.029 0.029 0.05" rgba="0 0.5 0 1" mass="0.1" condim="1"/>
      <joint type="free"/>
    </default>

    <default class="circularItems">
      <geom type="cylinder" size="0.029 0.02 0" rgba="0 0.5 0 1" mass="0.05" condim="1"/>
      <joint type="free"/>
    </default>

  </default>

<!-- Actuators -->
  <actuator>
    <motor name="pusher" joint="plate"/>
    <position name="slide_x" joint="slide_x"/>
  </actuator>

<!-- Lighting -->
  <visual>
    <headlight diffuse="0.6 0.6 0.6" ambient="0.1 0.1 0.1" specular="0 0 0"/>
    <rgba haze="0.15 0.25 0.35 1"/>
    <global azimuth="120" elevation="-20" offwidth="640" offheight="480"/>
  </visual>

<!-- Assets -->
  <asset>
    <texture type="skybox" builtin="gradient" rgb1="0.3 0.5 0.7" rgb2="0 0 0" width="512" height="3072"/>
    <texture type="2d" name="groundplane" builtin="checker" mark="edge" rgb1="0.2 0.3 0.4" rgb2="0.1 0.2 0.3"
      markrgb="0.8 0.8 0.8" width="300" height="300"/>
    <material name="groundplane" texture="groundplane" texuniform="true" texrepeat="5 5" reflectance="0.2"/>

    <texture type="2d" name="conveyor" builtin="gradient" mark="edge" rgb1="0.5 0.1 0.1" rgb2="0.8 0.1 0.1"
      markrgb="0.8 0.8 0.8" width="300" height="300"/>
    <material name="conveyor" texture="conveyor" texuniform="true" texrepeat="5 5" reflectance="0.2"/>
  </asset>

    <!-- MODEL TREE STARTS HERE -->
  <worldbody>
    <light pos="0 0 1.5" dir="0 0 -1" directional="true"/>
    <geom name="floor" size="0 0 0.05" type="plane" material="groundplane" condim="3"/>

    <!-- Camera model -->
    <body pos="0 0 1" euler="0 0 1.5708">
      <geom size="0.06 0.03 0.01" type="box"/>
      <camera name="rgbcam" mode="fixed" fovy="48.8"/>
    </body>

    <!-- Conveyor -->
    <body pos="0 0 0.2">
      <!-- Conveyor top surface -->
      <geom name="conveyor_geom" pos="0 0 -0.04" size="0.25 2 0.05" type="box" material="conveyor" friction="0 0 0" condim="1"/>
      <geom name="conveyor_friction_strip" pos="0 -1.5 0" size="0.25 0.01 0.0105" type="box" rgba="0.1 0.1 0.1 1" condim="3"/>
      
      <body>
        <!-- Mobile platform -->
        <body>
          <!-- pusher plate -->
          <geom size="0.02 0.15 0.04" pos="0 -1.6 0.06" type="box" condim="1"/>
          <joint name="plate" type="slide" stiffness="100" damping="10" axis="0 1 0"/>
        </body>
       
        <body childclass="small_enc">
          <!-- Enclosure for circularItems -->
          <geom pos="0 -1.54 0.62"/>
          <geom pos="0 -1.46 0.62"/>
        </body>

        <body childclass="large_enc">
          <!-- Enclosure for circularItems -->
          <geom pos="0.04 -1.5 0.55"/>
          <geom pos="-0.04 -1.5 0.55"/>
        </body>
        
        <!-- platform slider -->
        <joint name="slide_x" type="slide" axis="1 0 0" stiffness="1000" damping="100"/>
      </body>

    </body>





    <!-- solo dappa -->
    <body pos="0 1.75 0.25" childclass="circularItems"> <geom/><joint/> </body>

  </worldbody>

</mujoco>
